<?xml version="1.0"?>
<robot xmlns:xacro="http://www.ros.org/wiki/xacro">
	<!-- ARM LINKS/JOINTS -->
    <!-- Shoulder Roll and Elbow Roll Links are different for the 2 arms -->
    <link name="LShoulderDummy">
        <xacro:visuals_collisions_shoulder_roll side="L"/>
        <inertial>
            <!-- CENTER OF MASS -->
            <origin rpy="0 0 0" xyz="0.02455 0.00563 0.0033"/>
            <mass value="0.15777"/>
            <inertia ixx="0.00009389993" ixy="-0.00004714452" ixz="-0.00002699471" iyy="0.00037151879" iyz="-0.00000245977" izz="0.00034190083"/>
        </inertial>
    </link>
    <link name="RShoulderDummy">
        <xacro:visuals_collisions_shoulder_roll side="R"/>
        <inertial>
            <!-- CENTER OF MASS -->
            <origin rpy="0 0 0" xyz="0.02429 -0.00952 0.00320"/>
            <mass value="0.15974"/>
            <inertia ixx="0.00011012031" ixy="0.00007669131" ixz="-0.00002604607" iyy="0.00036757653" iyz="0.00001209828" izz="0.00035461772"/>
        </inertial>
    </link>
    <link name="LElbowDummy">
        <xacro:visuals_collisions_elbow_roll side="L"/>
        <inertial>
            <!-- CENTER OF MASS -->
            <origin rpy="0 0 0" xyz="0.02556 0.00281 0.00076"/>
            <mass value="0.07761"/>
            <inertia ixx="0.00002533220" ixy="-0.00000234271" ixz="0.00000007459" iyy="0.00008913220" iyz="-0.00000002655" izz="0.00008728726"/>
        </inertial>
    </link>
    <link name="RElbowDummy">
        <xacro:visuals_collisions_elbow_roll side="R"/>
        <inertial>
            <!-- CENTER OF MASS -->
            <origin rpy="0 0 0" xyz="0.02552 -0.00281 0.00090"/>
            <mass value="0.07778"/>
            <inertia ixx="0.00002539070" ixy="0.00000233243" ixz="-0.00000060117" iyy="0.00008922036" iyz="0.00000002694" izz="0.00008724843"/>
        </inertial>
    </link>
    <!-- XACRO -->
    <xacro:macro name="arm_links_joints" params="side reflect">
        <joint name="${side}ShoulderPitch" type="revolute">
            <parent link="torso"/>
            <child link="${side}Shoulder"/>
            <limit effort="${effort_type3*speed_red_type3A}" lower="-2.0857" upper="2.0857" velocity="3.0"/>
            <origin rpy="0 0 0" xyz="0 ${reflect*0.098} 0.1"/>
            <axis xyz="0 1 0"/>
        </joint>
        <link name="${side}Shoulder">
            <xacro:visuals_collisions_shoulder_pitch side="${side}"/>
            <inertial>
                <!-- CENTER OF MASS -->
                <origin rpy="0 0 0" xyz="-0.00165 ${reflect*(-0.02663)} 0.00014"/>
                <mass value="0.07504"/>
                <inertia ixx="0.00008428430" ixy="${reflect*-0.00000202802}" ixz="0.00000002338" iyy="0.00001415561" iyz="${reflect*-0.00000001972}" izz="0.00008641949"/>
            </inertial>
        </link>
        <joint name="${side}ElbowYaw" type="revolute">
            <parent link="${side}ShoulderDummy"/>
            <child link="${side}Elbow"/>
            <limit effort="${effort_type3*speed_red_type3A}" lower="-2.0857" upper="2.0857" velocity="3.0"/>
            <origin rpy="0 0 0" xyz="0.105 ${reflect*0.015} 0"/>
            <axis xyz="1 0 0"/>
        </joint>
        <link name="${side}Elbow">
            <inertial>
                <!-- CENTER OF MASS -->
                <origin rpy="0 0 0" xyz="-0.02744 0 -0.00014"/>
                <mass value="0.06483"/>
                <inertia ixx="0.00000559715" ixy="0.00000000421" ixz="0.00000004319" iyy="0.00007543312" iyz="-0.00000000184" izz="0.00007644339"/>
            </inertial>
        </link>
    </xacro:macro>
    <xacro:arm_links_joints reflect="1" side="L"/>
    <xacro:arm_links_joints reflect="-1" side="R"/>
    <!-- JOINTS THAT ARE NOT IDENTICAL TO 2 ENDS -->
    <joint name="LShoulderRoll" type="revolute">
        <parent link="LShoulder"/>
        <child link="LShoulderDummy"/>
        <limit effort="${effort_type3*speed_red_type3B}" lower="-0.3142" upper="1.3265" velocity="3.0"/>
        <origin rpy="0 0 0" xyz="0 0 0"/>
        <axis xyz="0 0 1"/>
    </joint>
    <joint name="RShoulderRoll" type="revolute">
        <parent link="RShoulder"/>
        <child link="RShoulderDummy"/>
        <limit effort="${effort_type3*speed_red_type3B}" lower="-1.3265" upper="0.3142" velocity="3.0"/>
        <origin rpy="0 0 0" xyz="0 0 0"/>
        <axis xyz="0 0 1"/>
    </joint>
    <joint name="LElbowRoll" type="revolute">
        <parent link="LElbow"/>
        <child link="LElbowDummy"/>
        <limit effort="${effort_type3*speed_red_type3B}" lower="-1.5446" upper="-0.0349" velocity="3.0"/>
        <origin rpy="0 0 0" xyz="0 0 0"/>
        <axis xyz="0 0 1"/>
    </joint>
    <joint name="RElbowRoll" type="revolute">
        <parent link="RElbow"/>
        <child link="RElbowDummy"/>
        <limit effort="${effort_type3*speed_red_type3B}" lower="0.0349" upper="1.5446" velocity="3.0"/>
        <origin rpy="0 0 0" xyz="0 0 0"/>
        <axis xyz="0 0 1"/>
    </joint>
    <!-- END OF ARM LINKS/JOINTS -->
</robot>
