<?xml version="1.0"?>
<robot xmlns:xacro="http://www.ros.org/wiki/xacro">
	<!-- LEFT LEG LINKS/JOINTS -->
    <joint name="LHipYawPitch" type="revolute">
        <parent link="base_link"/>
        <child link="LHipYaw"/>
        <limit effort="${effort_type1*speed_red_type1A}" lower="-1.145303" upper="0.740810" velocity="3.0"/>
        <origin rpy="0 0 0" xyz="0 0.05 -0.085"/>
        <axis xyz="0 0.707106 -0.707106"/>
    </joint>
    <link name="LHipYaw">
        <xacro:visuals_collisions_hip_yaw_pitch reflect="1" side="L"/>
        <inertial>
            <!-- CENTER OF MASS -->
            <origin rpy="0 0 0" xyz="-0.00781 -0.01114 0.02661"/>
            <mass value="0.06981"/>
            <inertia ixx="0.00008150233" ixy="-0.00000499449" ixz="0.00001274817" iyy="0.00010132555" iyz="0.00002345474" izz="0.000062626363"/>
        </inertial>
    </link>
    <joint name="LHipRoll" type="revolute">
        <parent link="LHipYaw"/>
        <child link="LHip"/>
        <limit effort="${effort_type1*speed_red_type1A}" lower="-0.379472" upper="0.790477" velocity="3.0"/>
        <origin rpy="0 0 0" xyz="0 0 0"/>
        <axis xyz="1 0 0"/>
    </joint>
    <link name="LHip">
        <xacro:visuals_collisions_hip_roll side="L"/>
        <inertial>
            <!-- CENTER OF MASS -->
            <origin rpy="0 0 0" xyz="-0.01549 0.00029 -0.00515"/>
            <mass value="0.13053"/>
            <inertia ixx="0.00002758354" ixy="-0.00000002233" ixz="-0.00000408164" iyy="0.00009827055" iyz="-0.00000000419" izz="0.00008809973"/>
        </inertial>
    </link>
    <joint name="LHipPitch" type="revolute">
        <parent link="LHip"/>
        <child link="LHipDummy"/>
        <limit effort="${effort_type1*speed_red_type1B}" lower="-1.535889" upper="0.484090" velocity="3.0"/>
        <origin rpy="0 0 0" xyz="0 0 0"/>
        <axis xyz="0 1 0"/>
    </joint>
    <link name="LHipDummy">
        <xacro:visuals_collisions_hip_pitch reflect="1" side="L"/>
        <inertial>
            <!-- CENTER OF MASS -->
            <origin rpy="0 0 0" xyz="0.00138 0.00221 -0.05373"/>
            <mass value="0.38968"/>
            <inertia ixx="0.00163671962" ixy="0.00000092451" ixz="0.00008530668" iyy="0.00159107278" iyz="0.00003836160" izz="0.00030374342"/>
        </inertial>
    </link>
    <joint name="LKneePitch" type="revolute">
        <parent link="LHipDummy"/>
        <child link="LKnee"/>
        <limit effort="${effort_type1*speed_red_type1B}" lower="-0.092346" upper="2.112528" velocity="3.0"/>
        <origin rpy="0 0 0" xyz="0 0 -0.1"/>
        <axis xyz="0 1 0"/>
    </joint>
    <link name="LKnee">
        <xacro:visuals_collisions_knee_pitch reflect="1" side="L"/>
        <inertial>
            <!-- CENTER OF MASS -->
            <origin rpy="0 0 0" xyz="0.00453 0.00225 -0.04936"/>
            <mass value="0.29142"/>
            <inertia ixx="0.00118207967" ixy="0.00000063362" ixz="0.00003649697" iyy="0.00112865226" iyz="0.00003949523" izz="0.00019322744"/>
        </inertial>
    </link>
    <joint name="LAnklePitch" type="revolute">
        <parent link="LKnee"/>
        <child link="l_ankle"/>
        <limit effort="${effort_type1*speed_red_type1B}" lower="-1.189516" upper="0.922747" velocity="3.0"/>
        <origin rpy="0 0 0" xyz="0 0 -0.1029"/>
        <axis xyz="0 1 0"/>
    </joint>
    <link name="l_ankle">
        <xacro:visuals_collisions_ankle_pitch side="L"/>
        <inertial>
            <!-- CENTER OF MASS -->
            <origin rpy="0 0 0" xyz="0.00045 0.00029 0.00685"/>
            <mass value="0.13416"/>
            <inertia ixx="0.00003850978" ixy="-0.00000002634" ixz="0.00000386194" iyy="0.00007426526" iyz="0.00000001834" izz="0.00005486540"/>
        </inertial>
    </link>
    <joint name="LAnkleRoll" type="revolute">
        <parent link="l_ankle"/>
        <child link="l_sole"/>
        <limit effort="${effort_type1*speed_red_type1A}" lower="-0.397880" upper="0.769001" velocity="3.0"/>
        <origin rpy="0 0 0" xyz="0 0 0"/>
        <axis xyz="1 0 0"/>
    </joint>
    <link name="l_sole">
        <xacro:visuals_collisions_ankle_roll side="L"/>
        <inertial>
            <!-- CENTER OF MASS -->
            <origin rpy="0 0 0" xyz="0.02540 -0.00332 -0.03239"/>
            <mass value="0.16184"/>
            <inertia ixx="0.00026930201" ixy="0.00000587505" ixz="0.00013913328" iyy="0.00064347385" iyz="-0.00001884917" izz="0.00052503477"/>
        </inertial>
    </link>
    <!-- RIGHT LEG LINKS/JOINTS -->
    <joint name="RHipYawPitch" type="revolute">
        <parent link="base_link"/>
        <child link="RHipYaw"/>
        <limit effort="${effort_type1*speed_red_type1A}" lower="-1.145303" upper="0.740810" velocity="3.0"/>
        <origin rpy="0 0 0" xyz="0 -0.05 -0.085"/>
        <axis xyz="0 0.707106 0.707106"/>
        <mimic joint="LHipYawPitch" multiplier="1" offset="0"/>
    </joint>
    <link name="RHipYaw">
        <xacro:visuals_collisions_hip_yaw_pitch reflect="-1" side="R"/>
        <inertial>
            <!-- CENTER OF MASS -->
            <origin rpy="0 0 0" xyz="-0.00766 0.01200 0.02716"/>
            <mass value="0.07118"/>
            <inertia ixx="0.00008997195" ixy="0.00000500219" ixz="0.00001273525" iyy="0.00010552611" iyz="-0.00002770080" izz="0.00006688724"/>
        </inertial>
    </link>
    <joint name="RHipRoll" type="revolute">
        <parent link="RHipYaw"/>
        <child link="RHip"/>
        <limit effort="${effort_type1*speed_red_type1A}" lower="-0.790477" upper="0.379472" velocity="3.0"/>
        <origin rpy="0 0 0" xyz="0 0 0"/>
        <axis xyz="1 0 0"/>
    </joint>
    <link name="RHip">
        <xacro:visuals_collisions_hip_roll side="R"/>
        <inertial>
            <!-- CENTER OF MASS -->
            <origin rpy="0 0 0" xyz="-0.01549 -0.00029 -0.00516"/>
            <mass value="0.13053"/>
            <inertia ixx="0.00002758654" ixy="-0.00000001919" ixz="-0.00000410822" iyy="0.00009826996" iyz="0.00000000251" izz="0.00008810332"/>
        </inertial>
    </link>
    <joint name="RHipPitch" type="revolute">
        <parent link="RHip"/>
        <child link="RHipDummy"/>
        <limit effort="${effort_type1*speed_red_type1B}" lower="-1.535889" upper="0.484090" velocity="3.0"/>
        <origin rpy="0 0 0" xyz="0 0 0"/>
        <axis xyz="0 1 0"/>
    </joint>
    <link name="RHipDummy">
        <xacro:visuals_collisions_hip_pitch reflect="-1" side="R"/>
        <inertial>
            <!-- CENTER OF MASS -->
            <origin rpy="0 0 0" xyz="0.00139 -0.00225 -0.05374"/>
            <mass value="0.38976"/>
            <inertia ixx="0.00163748205" ixy="-0.00000083954" ixz="0.00008588301" iyy="0.00159221403" iyz="-0.00003917626" izz="0.00030397824"/>
        </inertial>
    </link>
    <joint name="RKneePitch" type="revolute">
        <parent link="RHipDummy"/>
        <child link="RKnee"/>
        <limit effort="${effort_type1*speed_red_type1B}" lower="-0.103083" upper="2.120198" velocity="3.0"/>
        <origin rpy="0 0 0" xyz="0 0 -0.1"/>
        <axis xyz="0 1 0"/>
    </joint>
    <link name="RKnee">
        <xacro:visuals_collisions_knee_pitch reflect="-1" side="R"/>
        <inertial>
            <!-- CENTER OF MASS -->
            <origin rpy="0 0 0" xyz="0.00394 -0.00221 -0.04938"/>
            <mass value="0.29163"/>
            <inertia ixx="0.00118282956" ixy="-0.00000089650" ixz="0.00002799690" iyy="0.00112827851" iyz="-0.00003847604" izz="0.00019145277"/>
        </inertial>
    </link>
    <joint name="RAnklePitch" type="revolute">
        <parent link="RKnee"/>
        <child link="r_ankle"/>
        <limit effort="${effort_type1*speed_red_type1B}" lower="-1.186448" upper="0.932056" velocity="3.0"/>
        <origin rpy="0 0 0" xyz="0 0 -0.1029"/>
        <axis xyz="0 1 0"/>
    </joint>
    <link name="r_ankle">
        <xacro:visuals_collisions_ankle_pitch side="R"/>
        <inertial>
            <!-- CENTER OF MASS -->
            <origin rpy="0 0 0" xyz="0.00045 -0.00030 0.00684"/>
            <mass value="0.13415"/>
            <inertia ixx="0.00003850813" ixy="0.00000006434" ixz="0.00000387466" iyy="0.00007431082" iyz="-0.00000000458" izz="0.00005491312"/>
        </inertial>
    </link>
    <joint name="RAnkleRoll" type="revolute">
        <parent link="r_ankle"/>
        <child link="r_sole"/>
        <limit effort="${effort_type1*speed_red_type1A}" lower="-0.768992" upper="0.397935" velocity="3.0"/>
        <origin rpy="0 0 0" xyz="0 0 0"/>
        <axis xyz="1 0 0"/>
    </joint>
    <link name="r_sole">
        <xacro:visuals_collisions_ankle_roll side="R"/>
        <inertial>
            <!-- CENTER OF MASS -->
            <origin rpy="0 0 0" xyz="0.02540 -0.00332 -0.03239"/>
            <mass value="0.16171"/>
            <inertia ixx="0.00026930201" ixy="0.00000587505" ixz="0.00013913328" iyy="0.00064347385" iyz="-0.00001884917" izz="0.00052503477"/>
        </inertial>
    </link>
    <!-- END OF LEG LINKS/JOINTS -->
</robot>
